[2022-10-31 23:17:19,967] {taskinstance.py:1159} INFO - Dependencies all met for <TaskInstance: dados_climaticos.cria_pasta scheduled__2022-08-29T00:00:00+00:00 [queued]>
[2022-10-31 23:17:19,985] {taskinstance.py:1159} INFO - Dependencies all met for <TaskInstance: dados_climaticos.cria_pasta scheduled__2022-08-29T00:00:00+00:00 [queued]>
[2022-10-31 23:17:19,985] {taskinstance.py:1356} INFO - 
--------------------------------------------------------------------------------
[2022-10-31 23:17:19,985] {taskinstance.py:1357} INFO - Starting attempt 1 of 1
[2022-10-31 23:17:19,985] {taskinstance.py:1358} INFO - 
--------------------------------------------------------------------------------
[2022-10-31 23:17:21,073] {taskinstance.py:1377} INFO - Executing <Task(BashOperator): cria_pasta> on 2022-08-29 00:00:00+00:00
[2022-10-31 23:17:21,077] {standard_task_runner.py:52} INFO - Started process 57657 to run task
[2022-10-31 23:17:21,085] {standard_task_runner.py:79} INFO - Running: ['airflow', 'tasks', 'run', 'dados_climaticos', 'cria_pasta', 'scheduled__2022-08-29T00:00:00+00:00', '--job-id', '12', '--raw', '--subdir', 'DAGS_FOLDER/dados_climaticos.py', '--cfg-path', '/tmp/tmp7umgo9nb', '--error-file', '/tmp/tmph7yxseru']
[2022-10-31 23:17:21,087] {standard_task_runner.py:80} INFO - Job 12: Subtask cria_pasta
[2022-10-31 23:17:21,678] {task_command.py:370} INFO - Running <TaskInstance: dados_climaticos.cria_pasta scheduled__2022-08-29T00:00:00+00:00 [running]> on host nayara-S14SL01
[2022-10-31 23:17:23,372] {taskinstance.py:1569} INFO - Exporting the following env vars:
AIRFLOW_CTX_DAG_OWNER=airflow
AIRFLOW_CTX_DAG_ID=dados_climaticos
AIRFLOW_CTX_TASK_ID=cria_pasta
AIRFLOW_CTX_EXECUTION_DATE=2022-08-29T00:00:00+00:00
AIRFLOW_CTX_TRY_NUMBER=1
AIRFLOW_CTX_DAG_RUN_ID=scheduled__2022-08-29T00:00:00+00:00
[2022-10-31 23:17:23,375] {subprocess.py:62} INFO - Tmp dir root location: 
 /tmp
[2022-10-31 23:17:23,376] {subprocess.py:74} INFO - Running command: ['bash', '-c', 'mkdir -p "/home/millenagena/Documents/airflowalura/semana=2022-09-05"']
[2022-10-31 23:17:23,397] {subprocess.py:85} INFO - Output:
[2022-10-31 23:17:23,408] {subprocess.py:92} INFO - mkdir: não foi possível criar o diretório “/home/millenagena”: Permissão negada
[2022-10-31 23:17:23,409] {subprocess.py:96} INFO - Command exited with return code 1
[2022-10-31 23:17:23,434] {taskinstance.py:1889} ERROR - Task failed with exception
Traceback (most recent call last):
  File "/home/nayara/Documentos/airflowalura/venv/lib/python3.9/site-packages/airflow/operators/bash.py", line 194, in execute
    raise AirflowException(
airflow.exceptions.AirflowException: Bash command failed. The command returned a non-zero exit code 1.
[2022-10-31 23:17:23,441] {taskinstance.py:1395} INFO - Marking task as FAILED. dag_id=dados_climaticos, task_id=cria_pasta, execution_date=20220829T000000, start_date=20221101T021719, end_date=20221101T021723
[2022-10-31 23:17:24,063] {standard_task_runner.py:92} ERROR - Failed to execute job 12 for task cria_pasta (Bash command failed. The command returned a non-zero exit code 1.; 57657)
[2022-10-31 23:17:24,125] {local_task_job.py:156} INFO - Task exited with return code 1
[2022-10-31 23:17:25,128] {local_task_job.py:273} INFO - 0 downstream tasks scheduled from follow-on schedule check
[2022-10-31 23:22:49,216] {taskinstance.py:1159} INFO - Dependencies all met for <TaskInstance: dados_climaticos.cria_pasta scheduled__2022-08-29T00:00:00+00:00 [queued]>
[2022-10-31 23:22:49,274] {taskinstance.py:1159} INFO - Dependencies all met for <TaskInstance: dados_climaticos.cria_pasta scheduled__2022-08-29T00:00:00+00:00 [queued]>
[2022-10-31 23:22:49,274] {taskinstance.py:1356} INFO - 
--------------------------------------------------------------------------------
[2022-10-31 23:22:49,274] {taskinstance.py:1357} INFO - Starting attempt 1 of 1
[2022-10-31 23:22:49,274] {taskinstance.py:1358} INFO - 
--------------------------------------------------------------------------------
[2022-10-31 23:22:50,489] {taskinstance.py:1377} INFO - Executing <Task(BashOperator): cria_pasta> on 2022-08-29 00:00:00+00:00
[2022-10-31 23:22:50,501] {standard_task_runner.py:52} INFO - Started process 58498 to run task
[2022-10-31 23:22:50,522] {standard_task_runner.py:79} INFO - Running: ['airflow', 'tasks', 'run', 'dados_climaticos', 'cria_pasta', 'scheduled__2022-08-29T00:00:00+00:00', '--job-id', '12', '--raw', '--subdir', 'DAGS_FOLDER/dados_climaticos.py', '--cfg-path', '/tmp/tmp53mmsvbn', '--error-file', '/tmp/tmp_y2xx9dj']
[2022-10-31 23:22:50,525] {standard_task_runner.py:80} INFO - Job 12: Subtask cria_pasta
[2022-10-31 23:22:51,616] {task_command.py:370} INFO - Running <TaskInstance: dados_climaticos.cria_pasta scheduled__2022-08-29T00:00:00+00:00 [running]> on host nayara-S14SL01
[2022-10-31 23:22:52,308] {taskinstance.py:1569} INFO - Exporting the following env vars:
AIRFLOW_CTX_DAG_OWNER=airflow
AIRFLOW_CTX_DAG_ID=dados_climaticos
AIRFLOW_CTX_TASK_ID=cria_pasta
AIRFLOW_CTX_EXECUTION_DATE=2022-08-29T00:00:00+00:00
AIRFLOW_CTX_TRY_NUMBER=1
AIRFLOW_CTX_DAG_RUN_ID=scheduled__2022-08-29T00:00:00+00:00
[2022-10-31 23:22:52,311] {subprocess.py:62} INFO - Tmp dir root location: 
 /tmp
[2022-10-31 23:22:52,312] {subprocess.py:74} INFO - Running command: ['bash', '-c', 'mkdir -p "/home/millenagena/Documents/airflowalura/semana=2022-09-05"']
[2022-10-31 23:22:52,331] {subprocess.py:85} INFO - Output:
[2022-10-31 23:22:52,337] {subprocess.py:92} INFO - mkdir: não foi possível criar o diretório “/home/millenagena”: Permissão negada
[2022-10-31 23:22:52,338] {subprocess.py:96} INFO - Command exited with return code 1
[2022-10-31 23:22:52,367] {taskinstance.py:1889} ERROR - Task failed with exception
Traceback (most recent call last):
  File "/home/nayara/Documentos/airflowalura/venv/lib/python3.9/site-packages/airflow/operators/bash.py", line 194, in execute
    raise AirflowException(
airflow.exceptions.AirflowException: Bash command failed. The command returned a non-zero exit code 1.
[2022-10-31 23:22:52,374] {taskinstance.py:1395} INFO - Marking task as FAILED. dag_id=dados_climaticos, task_id=cria_pasta, execution_date=20220829T000000, start_date=20221101T022249, end_date=20221101T022252
[2022-10-31 23:22:52,808] {standard_task_runner.py:92} ERROR - Failed to execute job 12 for task cria_pasta (Bash command failed. The command returned a non-zero exit code 1.; 58498)
[2022-10-31 23:22:52,827] {local_task_job.py:156} INFO - Task exited with return code 1
[2022-10-31 23:22:53,372] {local_task_job.py:273} INFO - 0 downstream tasks scheduled from follow-on schedule check
[2022-10-31 23:28:55,935] {taskinstance.py:1159} INFO - Dependencies all met for <TaskInstance: dados_climaticos.cria_pasta scheduled__2022-08-29T00:00:00+00:00 [queued]>
[2022-10-31 23:28:55,959] {taskinstance.py:1159} INFO - Dependencies all met for <TaskInstance: dados_climaticos.cria_pasta scheduled__2022-08-29T00:00:00+00:00 [queued]>
[2022-10-31 23:28:55,959] {taskinstance.py:1356} INFO - 
--------------------------------------------------------------------------------
[2022-10-31 23:28:55,960] {taskinstance.py:1357} INFO - Starting attempt 1 of 1
[2022-10-31 23:28:55,960] {taskinstance.py:1358} INFO - 
--------------------------------------------------------------------------------
[2022-10-31 23:28:56,458] {taskinstance.py:1377} INFO - Executing <Task(BashOperator): cria_pasta> on 2022-08-29 00:00:00+00:00
[2022-10-31 23:28:56,463] {standard_task_runner.py:52} INFO - Started process 59259 to run task
[2022-10-31 23:28:56,470] {standard_task_runner.py:79} INFO - Running: ['airflow', 'tasks', 'run', 'dados_climaticos', 'cria_pasta', 'scheduled__2022-08-29T00:00:00+00:00', '--job-id', '12', '--raw', '--subdir', 'DAGS_FOLDER/dados_climaticos.py', '--cfg-path', '/tmp/tmpe3c7hs6c', '--error-file', '/tmp/tmp0icvhij7']
[2022-10-31 23:28:56,471] {standard_task_runner.py:80} INFO - Job 12: Subtask cria_pasta
[2022-10-31 23:28:57,029] {task_command.py:370} INFO - Running <TaskInstance: dados_climaticos.cria_pasta scheduled__2022-08-29T00:00:00+00:00 [running]> on host nayara-S14SL01
[2022-10-31 23:28:58,374] {taskinstance.py:1569} INFO - Exporting the following env vars:
AIRFLOW_CTX_DAG_OWNER=airflow
AIRFLOW_CTX_DAG_ID=dados_climaticos
AIRFLOW_CTX_TASK_ID=cria_pasta
AIRFLOW_CTX_EXECUTION_DATE=2022-08-29T00:00:00+00:00
AIRFLOW_CTX_TRY_NUMBER=1
AIRFLOW_CTX_DAG_RUN_ID=scheduled__2022-08-29T00:00:00+00:00
[2022-10-31 23:28:58,376] {subprocess.py:62} INFO - Tmp dir root location: 
 /tmp
[2022-10-31 23:28:58,377] {subprocess.py:74} INFO - Running command: ['bash', '-c', 'mkdir -p "/home/millenagena/Documents/airflowalura/semana=2022-09-05"']
[2022-10-31 23:28:58,395] {subprocess.py:85} INFO - Output:
[2022-10-31 23:28:58,399] {subprocess.py:92} INFO - mkdir: não foi possível criar o diretório “/home/millenagena”: Permissão negada
[2022-10-31 23:28:58,400] {subprocess.py:96} INFO - Command exited with return code 1
[2022-10-31 23:28:58,420] {taskinstance.py:1889} ERROR - Task failed with exception
Traceback (most recent call last):
  File "/home/nayara/Documentos/airflowalura/venv/lib/python3.9/site-packages/airflow/operators/bash.py", line 194, in execute
    raise AirflowException(
airflow.exceptions.AirflowException: Bash command failed. The command returned a non-zero exit code 1.
[2022-10-31 23:28:58,425] {taskinstance.py:1395} INFO - Marking task as FAILED. dag_id=dados_climaticos, task_id=cria_pasta, execution_date=20220829T000000, start_date=20221101T022855, end_date=20221101T022858
[2022-10-31 23:28:58,826] {standard_task_runner.py:92} ERROR - Failed to execute job 12 for task cria_pasta (Bash command failed. The command returned a non-zero exit code 1.; 59259)
[2022-10-31 23:28:58,853] {local_task_job.py:156} INFO - Task exited with return code 1
[2022-10-31 23:28:59,302] {local_task_job.py:273} INFO - 0 downstream tasks scheduled from follow-on schedule check
